public void verify(VerificationData data) {
    AssertionError error = null;

    timer.start();
    while (timer.isCounting()) {
        try {
            delegate.verify(data);

            if (returnOnSuccess) {
                return;
            } else {
                error = null;
            }
        } catch (MockitoAssertionError e) {
            error = handleVerifyException(e);
        }
        catch (org.mockito.exceptions.verification.junit.ArgumentsAreDifferent e) {
            error = handleVerifyException(e);
        }
        catch (Exception e) { // Added a catch block for any other exceptions
            throw new RuntimeException("An unexpected exception occurred during verification", e);
        }
    }

    if (error != null) {
        throw error;
    }
}